Workbook

Sheet LEIA-ME
A1: Base Fictícia de E-commerce – Estudo e Portfólio
A2: Período: 01/01/2025 a 30/09/2026 · 9.798 linhas de venda · 5.991 pedidos · 46 produtos · 450 clientes
A3: Todos os dados são FICTÍCIOS (gerados aleatoriamente). Podem ser usados livremente em portfólio.
A5: ABA | B5: CONTEÚDO / USO
A6: Resumo | B6: KPIs, faturamento mensal, por categoria e por canal (tudo em fórmulas) + gráficos. Modelo para o Pacote 2.
A7: dProdutos | B7: Dimensão de produtos: categoria, fornecedor, custo, preço, margem e estoque mínimo.
A8: dClientes | B8: Dimensão de clientes: cidade, UF, região, data de cadastro.
A9: dVendedores | B9: Dimensão de vendedores com canal principal e meta mensal (para medidas de % da meta no Power BI).
A10: dCalendario | B10: Tabela calendário pronta (ano, mês, trimestre, dia da semana) – use no Power BI.
A11: fVendas | B11: Tabela fato: 1 linha por item de pedido. Item = 1 marca a 1ª linha do pedido (use para contar pedidos).
A12: fCompras | B12: Entradas de estoque (notas fiscais de compra dos fornecedores).
A13: fEstoque | B13: Posição de estoque: inicial + entradas − saídas, com alerta OK / REPOR / SEM ESTOQUE.
A14: Base_Suja | B14: Cadastro BAGUNÇADO de propósito (duplicados, linhas vazias, datas/telefones/valores fora do padrão). Treino do Pacote 1 com Power Query.
A16: CONVENÇÕES
A17: Texto azul | B17: Valores digitados (premissas) que você pode alterar: custo, preço, estoque mínimo, estoque inicial.
A18: Texto preto | B18: Fórmulas – recalculam sozinhas.
A19: Status | B19: Pedidos 'Cancelado' não entram no faturamento, lucro nem nas saídas de estoque. 'Devolvido' foi mantido como venda (exercício: tratar devoluções).
A20: Frete | B20: Cobrado do cliente, registrado apenas na 1ª linha (Item = 1) de cada pedido; não entra no Valor_Liquido.
A21: Sazonalidade | B21: Pico em novembro (Black Friday, 24 a 30/11 com volume ×3 e desconto mínimo de 20%) e dezembro; crescimento de ~25% ao ano.
A23: POWER BI | B23: Obter Dados > Excel > marque as tabelas tb* (tbVendas, tbProdutos, tbClientes, tbVendedores, tbCalendario, tbCompras).
B24: Relacione: tbVendas[ID_Produto]→tbProdutos, [ID_Cliente]→tbClientes, [ID_Vendedor]→tbVendedores, [Data]→tbCalendario[Data].

Sheet Resumo
A1: Resumo Gerencial – Base Fictícia de E-commerce
A2: Valores calculados por fórmula a partir de fVendas (exclui pedidos cancelados).
A4: Faturamento Líquido | B4: =SUMIFS(fVendas!$P$2:$P$9799,fVendas!$I$2:$I$9799,"<>Cancelado") -> 1958696.5
A5: Lucro Bruto | B5: =SUM(fVendas!$R$2:$R$9799) -> 939185.51
A6: Margem % | B6: =IF(B4=0,0,B5/B4) -> 0.47949517
A7: Nº de Pedidos | B7: =COUNTIFS(fVendas!$B$2:$B$9799,1,fVendas!$I$2:$I$9799,"<>Cancelado") -> 5625
A8: Ticket Médio | B8: =IF(B7=0,0,B4/B7) -> 348.21271
A9: Itens Vendidos | B9: =SUMIFS(fVendas!$J$2:$J$9799,fVendas!$I$2:$I$9799,"<>Cancelado") -> 11668
A10: Produtos para Repor | B10: =COUNTIF(fEstoque!$H$2:$H$47,"REPOR")+COUNTIF(fEstoque!$H$2:$H$47,"SEM ESTOQUE") -> 14
A13: Mês | B13: Faturamento | C13: Lucro | D13: Margem %
A14: 45658 | B14: =SUMIFS(fVendas!$P$2:$P$9799,fVendas!$C$2:$C$9799,">="&A14,fVendas!$C$2:$C$9799,"<"&EDATE(A14,1),fVendas!$I$2:$I$9799,"<>Cancelado") -> 62937.44 | C14: =SUMIFS(fVendas!$R$2:$R$9799,fVendas!$C$2:$C$9799,">="&A14,fVendas!$C$2:$C$9799,"<"&EDATE(A14,1)) -> 30612.14 | D14: =IF(B14=0,0,C14/B14) -> 0.48638998
A15: 45689 | B15: =SUMIFS(fVendas!$P$2:$P$9799,fVendas!$C$2:$C$9799,">="&A15,fVendas!$C$2:$C$9799,"<"&EDATE(A15,1),fVendas!$I$2:$I$9799,"<>Cancelado") -> 54746.7 | C15: =SUMIFS(fVendas!$R$2:$R$9799,fVendas!$C$2:$C$9799,">="&A15,fVendas!$C$2:$C$9799,"<"&EDATE(A15,1)) -> 26290.12 | D15: =IF(B15=0,0,C15/B15) -> 0.48021378
A16: 45717 | B16: =SUMIFS(fVendas!$P$2:$P$9799,fVendas!$C$2:$C$9799,">="&A16,fVendas!$C$2:$C$9799,"<"&EDATE(A16,1),fVendas!$I$2:$I$9799,"<>Cancelado") -> 72285.885 | C16: =SUMIFS(fVendas!$R$2:$R$9799,fVendas!$C$2:$C$9799,">="&A16,fVendas!$C$2:$C$9799,"<"&EDATE(A16,1)) -> 35906.045 | D16: =IF(B16=0,0,C16/B16) -> 0.49672277
A17: 45748 | B17: =SUMIFS(fVendas!$P$2:$P$9799,fVendas!$C$2:$C$9799,">="&A17,fVendas!$C$2:$C$9799,"<"&EDATE(A17,1),fVendas!$I$2:$I$9799,"<>Cancelado") -> 67047.21 | C17: =SUMIFS(fVendas!$R$2:$R$9799,fVendas!$C$2:$C$9799,">="&A17,fVendas!$C$2:$C$9799,"<"&EDATE(A17,1)) -> 31747.3 | D17: =IF(B17=0,0,C17/B17) -> 0.47350665
A18: 45778 | B18: =SUMIFS(fVendas!$P$2:$P$9799,fVendas!$C$2:$C$9799,">="&A18,fVendas!$C$2:$C$9799,"<"&EDATE(A18,1),fVendas!$I$2:$I$9799,"<>Cancelado") -> 89455.555 | C18: =SUMIFS(fVendas!$R$2:$R$9799,fVendas!$C$2:$C$9799,">="&A18,fVendas!$C$2:$C$9799,"<"&EDATE(A18,1)) -> 42725.405 | D18: =IF(B18=0,0,C18/B18) -> 0.47761601
A19: 45809 | B19: =SUMIFS(fVendas!$P$2:$P$9799,fVendas!$C$2:$C$9799,">="&A19,fVendas!$C$2:$C$9799,"<"&EDATE(A19,1),fVendas!$I$2:$I$9799,"<>Cancelado") -> 77681.34 | C19: =SUMIFS(fVendas!$R$2:$R$9799,fVendas!$C$2:$C$9799,">="&A19,fVendas!$C$2:$C$9799,"<"&EDATE(A19,1)) -> 37267.27 | D19: =IF(B19=0,0,C19/B19) -> 0.47974546
A20: 45839 | B20: =SUMIFS(fVendas!$P$2:$P$9799,fVendas!$C$2:$C$9799,">="&A20,fVendas!$C$2:$C$9799,"<"&EDATE(A20,1),fVendas!$I$2:$I$9799,"<>Cancelado") -> 80570.93 | C20: =SUMIFS(fVendas!$R$2:$R$9799,fVendas!$C$2:$C$9799,">="&A20,fVendas!$C$2:$C$9799,"<"&EDATE(A20,1)) -> 39371.84 | D20: =IF(B20=0,0,C20/B20) -> 0.48866061
A21: 45870 | B21: =SUMIFS(fVendas!$P$2:$P$9799,fVendas!$C$2:$C$9799,">="&A21,fVendas!$C$2:$C$9799,"<"&EDATE(A21,1),fVendas!$I$2:$I$9799,"<>Cancelado") -> 89692.79 | C21: =SUMIFS(fVendas!$R$2:$R$9799,fVendas!$C$2:$C$9799,">="&A21,fVendas!$C$2:$C$9799,"<"&EDATE(A21,1)) -> 43159.9 | D21: =IF(B21=0,0,C21/B21) -> 0.48119698
A22: 45901 | B22: =SUMIFS(fVendas!$P$2:$P$9799,fVendas!$C$2:$C$9799,">="&A22,fVendas!$C$2:$C$9799,"<"&EDATE(A22,1),fVendas!$I$2:$I$9799,"<>Cancelado") -> 80779.595 | C22: =SUMIFS(fVendas!$R$2:$R$9799,fVendas!$C$2:$C$9799,">="&A22,fVendas!$C$2:$C$9799,"<"&EDATE(A22,1)) -> 39067.085 | D22: =IF(B22=0,0,C22/B22) -> 0.48362566
A23: 45931 | B23: =SUMIFS(fVendas!$P$2:$P$9799,fVendas!$C$2:$C$9799,">="&A23,fVendas!$C$2:$C$9799,"<"&EDATE(A23,1),fVendas!$I$2:$I$9799,"<>Cancelado") -> 83750.74 | C23: =SUMIFS(fVendas!$R$2:$R$9799,fVendas!$C$2:$C$9799,">="&A23,fVendas!$C$2:$C$9799,"<"&EDATE(A23,1)) -> 40086.75 | D23: =IF(B23=0,0,C23/B23) -> 0.47864353
A24: 45962 | B24: =SUMIFS(fVendas!$P$2:$P$9799,fVendas!$C$2:$C$9799,">="&A24,fVendas!$C$2:$C$9799,"<"&EDATE(A24,1),fVendas!$I$2:$I$9799,"<>Cancelado") -> 210143.59 | C24: =SUMIFS(fVendas!$R$2:$R$9799,fVendas!$C$2:$C$9799,">="&A24,fVendas!$C$2:$C$9799,"<"&EDATE(A24,1)) -> 92084.3 | D24: =IF(B24=0,0,C24/B24) -> 0.43819704
A25: 45992 | B25: =SUMIFS(fVendas!$P$2:$P$9799,fVendas!$C$2:$C$9799,">="&A25,fVendas!$C$2:$C$9799,"<"&EDATE(A25,1),fVendas!$I$2:$I$9799,"<>Cancelado") -> 150636.68 | C25: =SUMIFS(fVendas!$R$2:$R$9799,fVendas!$C$2:$C$9799,">="&A25,fVendas!$C$2:$C$9799,"<"&EDATE(A25,1)) -> 73163.845 | D25: =IF(B25=0,0,C25/B25) -> 0.48569739
... A34: 46266 | B34: =SUMIFS(fVendas!$P$2:$P$9799,fVendas!$C$2:$C$9799,">="&A34,fVendas!$C$2:$C$9799,"<"&EDATE(A34,1),fVendas!$I$2:$I$9799,"<>Cancelado") -> 100768.32 | C34: =SUMIFS(fVendas!$R$2:$R$9799,fVendas!$C$2:$C$9799,">="&A34,fVendas!$C$2:$C$9799,"<"&EDATE(A34,1)) -> 48725.285 | D34: =IF(B34=0,0,C34/B34) -> 0.48353776
A37: Categoria | B37: Faturamento | C37: Lucro | D37: Margem %
A38: Moda Feminina | B38: =SUMIFS(fVendas!$P$2:$P$9799,fVendas!$S$2:$S$9799,A38,fVendas!$I$2:$I$9799,"<>Cancelado") -> 267538.41 | C38: =SUMIFS(fVendas!$R$2:$R$9799,fVendas!$S$2:$S$9799,A38) -> 128869.98 | D38: =IF(B38=0,0,C38/B38) -> 0.48168777
A39: Moda Masculina | B39: =SUMIFS(fVendas!$P$2:$P$9799,fVendas!$S$2:$S$9799,A39,fVendas!$I$2:$I$9799,"<>Cancelado") -> 306374.28 | C39: =SUMIFS(fVendas!$R$2:$R$9799,fVendas!$S$2:$S$9799,A39) -> 137868.11 | D39: =IF(B39=0,0,C39/B39) -> 0.44999899
A40: Calçados | B40: =SUMIFS(fVendas!$P$2:$P$9799,fVendas!$S$2:$S$9799,A40,fVendas!$I$2:$I$9799,"<>Cancelado") -> 326282.2 | C40: =SUMIFS(fVendas!$R$2:$R$9799,fVendas!$S$2:$S$9799,A40) -> 163557.05 | D40: =IF(B40=0,0,C40/B40) -> 0.50127482
A41: Acessórios | B41: =SUMIFS(fVendas!$P$2:$P$9799,fVendas!$S$2:$S$9799,A41,fVendas!$I$2:$I$9799,"<>Cancelado") -> 310318.17 | C41: =SUMIFS(fVendas!$R$2:$R$9799,fVendas!$S$2:$S$9799,A41) -> 168869.89 | D41: =IF(B41=0,0,C41/B41) -> 0.54418306
A42: Casa | B42: =SUMIFS(fVendas!$P$2:$P$9799,fVendas!$S$2:$S$9799,A42,fVendas!$I$2:$I$9799,"<>Cancelado") -> 455810.49 | C42: =SUMIFS(fVendas!$R$2:$R$9799,fVendas!$S$2:$S$9799,A42) -> 196307.59 | D42: =IF(B42=0,0,C42/B42) -> 0.43067809
A43: Eletrônicos | B43: =SUMIFS(fVendas!$P$2:$P$9799,fVendas!$S$2:$S$9799,A43,fVendas!$I$2:$I$9799,"<>Cancelado") -> 173869.26 | C43: =SUMIFS(fVendas!$R$2:$R$9799,fVendas!$S$2:$S$9799,A43) -> 88698.73 | D43: =IF(B43=0,0,C43/B43) -> 0.51014613
A44: Beleza | B44: =SUMIFS(fVendas!$P$2:$P$9799,fVendas!$S$2:$S$9799,A44,fVendas!$I$2:$I$9799,"<>Cancelado") -> 118503.71 | C44: =SUMIFS(fVendas!$R$2:$R$9799,fVendas!$S$2:$S$9799,A44) -> 55014.155 | D44: =IF(B44=0,0,C44/B44) -> 0.46423996
A47: Canal | B47: Faturamento | C47: Nº Pedidos | D47: Ticket Médio
A48: Loja Virtual (Nuvemshop) | B48: =SUMIFS(fVendas!$P$2:$P$9799,fVendas!$G$2:$G$9799,A48,fVendas!$I$2:$I$9799,"<>Cancelado") -> 567274.6 | C48: =COUNTIFS(fVendas!$G$2:$G$9799,A48,fVendas!$B$2:$B$9799,1,fVendas!$I$2:$I$9799,"<>Cancelado") -> 1640 | D48: =IF(C48=0,0,B48/C48) -> 345.89915
A49: Loja Virtual (Yampi) | B49: =SUMIFS(fVendas!$P$2:$P$9799,fVendas!$G$2:$G$9799,A49,fVendas!$I$2:$I$9799,"<>Cancelado") -> 301629.68 | C49: =COUNTIFS(fVendas!$G$2:$G$9799,A49,fVendas!$B$2:$B$9799,1,fVendas!$I$2:$I$9799,"<>Cancelado") -> 840 | D49: =IF(C49=0,0,B49/C49) -> 359.08295
A50: Mercado Livre | B50: =SUMIFS(fVendas!$P$2:$P$9799,fVendas!$G$2:$G$9799,A50,fVendas!$I$2:$I$9799,"<>Cancelado") -> 395923.8 | C50: =COUNTIFS(fVendas!$G$2:$G$9799,A50,fVendas!$B$2:$B$9799,1,fVendas!$I$2:$I$9799,"<>Cancelado") -> 1129 | D50: =IF(C50=0,0,B50/C50) -> 350.68539
A51: Shopee | B51: =SUMIFS(fVendas!$P$2:$P$9799,fVendas!$G$2:$G$9799,A51,fVendas!$I$2:$I$9799,"<>Cancelado") -> 357955.05 | C51: =COUNTIFS(fVendas!$G$2:$G$9799,A51,fVendas!$B$2:$B$9799,1,fVendas!$I$2:$I$9799,"<>Cancelado") -> 1044 | D51: =IF(C51=0,0,B51/C51) -> 342.86882
A52: Instagram | B52: =SUMIFS(fVendas!$P$2:$P$9799,fVendas!$G$2:$G$9799,A52,fVendas!$I$2:$I$9799,"<>Cancelado") -> 180994.49 | C52: =COUNTIFS(fVendas!$G$2:$G$9799,A52,fVendas!$B$2:$B$9799,1,fVendas!$I$2:$I$9799,"<>Cancelado") -> 516 | D52: =IF(C52=0,0,B52/C52) -> 350.76453
A53: WhatsApp | B53: =SUMIFS(fVendas!$P$2:$P$9799,fVendas!$G$2:$G$9799,A53,fVendas!$I$2:$I$9799,"<>Cancelado") -> 154918.88 | C53: =COUNTIFS(fVendas!$G$2:$G$9799,A53,fVendas!$B$2:$B$9799,1,fVendas!$I$2:$I$9799,"<>Cancelado") -> 456 | D53: =IF(C53=0,0,B53/C53) -> 339.73439

Sheet dProdutos
A1: ID_Produto | B1: SKU | C1: Produto | D1: Categoria | E1: Fornecedor | F1: Custo_Unit | G1: Preco_Venda | H1: Margem_% | I1: Estoque_Minimo
A2: P001 | B2: SKU-MOD-001 | C2: Vestido Midi | D2: Moda Feminina | E2: Fornecedor Goiânia | F2: 69.44 | G2: 179.9 | H2: =(G2-F2)/G2 -> 0.61400778 | I2: 15
A3: P002 | B3: SKU-MOD-002 | C3: Blusa Cropped | D3: Moda Feminina | E3: Fábrica Própria | F3: 107.88 | G3: 198.9 | H3: =(G3-F3)/G3 -> 0.45761689 | I3: 25
A4: P003 | B4: SKU-MOD-003 | C4: Calça Wide Leg | D4: Moda Feminina | E4: Atacado Brás SP | F4: 26.12 | G4: 64.9 | H4: =(G4-F4)/G4 -> 0.59753467 | I4: 10
A5: P004 | B5: SKU-MOD-004 | C5: Saia Plissada | D5: Moda Feminina | E5: Fábrica Própria | F5: 91.55 | G5: 165.9 | H5: =(G5-F5)/G5 -> 0.44816154 | I5: 25
A6: P005 | B6: SKU-MOD-005 | C6: Macacão Longo | D6: Moda Feminina | E6: Dropi Distribuidora | F6: 98.14 | G6: 170.9 | H6: =(G6-F6)/G6 -> 0.42574605 | I6: 15
A7: P006 | B7: SKU-MOD-006 | C7: Blazer Alfaiataria | D7: Moda Feminina | E7: Atacado Brás SP | F7: 88.59 | G7: 191.9 | H7: =(G7-F7)/G7 -> 0.53835331 | I7: 20
A8: P007 | B8: SKU-MOD-007 | C8: Cardigan Tricô | D8: Moda Feminina | E8: Fornecedor Goiânia | F8: 36.71 | G8: 77.9 | H8: =(G8-F8)/G8 -> 0.52875481 | I8: 30
A9: P008 | B9: SKU-MOD-008 | C9: Short Jeans | D9: Moda Feminina | E9: Import Sul | F9: 42.52 | G9: 108.9 | H9: =(G9-F9)/G9 -> 0.60955005 | I9: 25
A10: P009 | B10: SKU-MOD-009 | C10: Camiseta Básica | D10: Moda Masculina | E10: Fábrica Própria | F10: 29.68 | G10: 65.9 | H10: =(G10-F10)/G10 -> 0.54962064 | I10: 20
A11: P010 | B11: SKU-MOD-010 | C11: Camisa Social | D11: Moda Masculina | E11: Dropi Distribuidora | F11: 96.59 | G11: 175.9 | H11: =(G11-F11)/G11 -> 0.45088118 | I11: 20
A12: P011 | B12: SKU-MOD-011 | C12: Bermuda Sarja | D12: Moda Masculina | E12: Dropi Distribuidora | F12: 155.62 | G12: 265.9 | H12: =(G12-F12)/G12 -> 0.41474238 | I12: 25
A13: P012 | B13: SKU-MOD-012 | C13: Calça Chino | D13: Moda Masculina | E13: Fornecedor Goiânia | F13: 88.32 | G13: 188.9 | H13: =(G13-F13)/G13 -> 0.53245103 | I13: 20
... A47: P046 | B47: SKU-BEL-046 | C47: Hidratante Corporal | D47: Beleza | E47: Dropi Distribuidora | F47: 90.42 | G47: 153.9 | H47: =(G47-F47)/G47 -> 0.41247563 | I47: 10

Sheet dClientes
A1: ID_Cliente | B1: Nome | C1: Email | D1: Genero | E1: Cidade | F1: UF | G1: Regiao | H1: Data_Cadastro
A2: C0001 | B2: Gustavo Lima | C2: gustavo.lima1@exemplo.com | D2: M | E2: Brasília | F2: DF | G2: Centro-Oeste | H2: 46061
A3: C0002 | B3: Marcos Gomes | C3: marcos.gomes2@exemplo.com | D3: M | E3: Belo Horizonte | F3: MG | G3: Sudeste | H3: 46006
A4: C0003 | B4: Rafael Rodrigues | C4: rafael.rodrigues3@exemplo.com | D4: M | E4: São Paulo | F4: SP | G4: Sudeste | H4: 45480
A5: C0004 | B5: Daniela Dias | C5: daniela.dias4@exemplo.com | D5: F | E5: Salvador | F5: BA | G5: Nordeste | H5: 45320
A6: C0005 | B6: Carlos Santos | C6: carlos.santos5@exemplo.com | D6: M | E6: São Paulo | F6: SP | G6: Sudeste | H6: 45746
A7: C0006 | B7: Thiago Barbosa | C7: thiago.barbosa6@exemplo.com | D7: M | E7: São Paulo | F7: SP | G7: Sudeste | H7: 45778
A8: C0007 | B8: Fernanda Ferreira | C8: fernanda.ferreira7@exemplo.com | D8: F | E8: São Paulo | F8: SP | G8: Sudeste | H8: 45327
A9: C0008 | B9: Sofia Martins | C9: sofia.martins8@exemplo.com | D9: F | E9: São Paulo | F9: SP | G9: Sudeste | H9: 45841
A10: C0009 | B10: Sofia Dias | C10: sofia.dias9@exemplo.com | D10: F | E10: Porto Alegre | F10: RS | G10: Sul | H10: 45892
A11: C0010 | B11: Fernanda Carvalho | C11: fernanda.carvalho10@exemplo.com | D11: F | E11: Florianópolis | F11: SC | G11: Sul | H11: 45836
A12: C0011 | B12: Vinícius Costa | C12: vinicius.costa11@exemplo.com | D12: M | E12: Brasília | F12: DF | G12: Centro-Oeste | H12: 45467
A13: C0012 | B13: Carlos Pereira | C13: carlos.pereira12@exemplo.com | D13: M | E13: Rio de Janeiro | F13: RJ | G13: Sudeste | H13: 45392
... A451: C0450 | B451: Daniela Dias | C451: daniela.dias450@exemplo.com | D451: F | E451: Porto Alegre | F451: RS | G451: Sul | H451: 45629

Sheet dVendedores
A1: ID_Vendedor | B1: Vendedor | C1: Canal_Principal | D1: Regiao | E1: Meta_Mensal
A2: V01 | B2: Ana Souza | C2: Marketplace | D2: Sudeste | E2: 28000
A3: V02 | B3: Bruno Lima | C3: Loja Virtual | D3: Sudeste | E3: 32000
A4: V03 | B4: Carla Mendes | C4: Loja Virtual | D4: Sul | E4: 20000
A5: V04 | B5: Diego Rocha | C5: WhatsApp | D5: Nordeste | E5: 15000
A6: V05 | B6: Elisa Martins | C6: Instagram | D6: Centro-Oeste | E6: 22000
A7: V06 | B7: Felipe Alves | C7: Marketplace | D7: Sul | E7: 24000
A8: V07 | B8: Gabriela Nunes | C8: WhatsApp | D8: Norte | E8: 12000
A9: V08 | B9: Henrique Costa | C9: Instagram | D9: Nordeste | E9: 18000

Sheet dCalendario
A1: Data | B1: Ano | C1: Mes_Num | D1: Mes_Nome | E1: Ano_Mes | F1: Trimestre | G1: Dia_Semana | H1: Fim_de_Semana
A2: 45658 | B2: =YEAR(A2) -> 2025 | C2: =MONTH(A2) -> 1 | D2: =INDEX({"Jan","Fev","Mar","Abr","Mai","Jun","Jul","Ago","Set","Out","Nov","Dez"},C2) -> Jan | E2: =TEXT(A2,"yyyy-mm") -> 2025-01 | F2: ="T"&ROUNDUP(C2/3,0) -> T1 | G2: =INDEX({"Dom","Seg","Ter","Qua","Qui","Sex","Sáb"},WEEKDAY(A2)) -> Qua | H2: =IF(OR(WEEKDAY(A2)=1,WEEKDAY(A2)=7),"Sim","Não") -> Não
A3: 45659 | B3: =YEAR(A3) -> 2025 | C3: =MONTH(A3) -> 1 | D3: =INDEX({"Jan","Fev","Mar","Abr","Mai","Jun","Jul","Ago","Set","Out","Nov","Dez"},C3) -> Jan | E3: =TEXT(A3,"yyyy-mm") -> 2025-01 | F3: ="T"&ROUNDUP(C3/3,0) -> T1 | G3: =INDEX({"Dom","Seg","Ter","Qua","Qui","Sex","Sáb"},WEEKDAY(A3)) -> Qui | H3: =IF(OR(WEEKDAY(A3)=1,WEEKDAY(A3)=7),"Sim","Não") -> Não
A4: 45660 | B4: =YEAR(A4) -> 2025 | C4: =MONTH(A4) -> 1 | D4: =INDEX({"Jan","Fev","Mar","Abr","Mai","Jun","Jul","Ago","Set","Out","Nov","Dez"},C4) -> Jan | E4: =TEXT(A4,"yyyy-mm") -> 2025-01 | F4: ="T"&ROUNDUP(C4/3,0) -> T1 | G4: =INDEX({"Dom","Seg","Ter","Qua","Qui","Sex","Sáb"},WEEKDAY(A4)) -> Sex | H4: =IF(OR(WEEKDAY(A4)=1,WEEKDAY(A4)=7),"Sim","Não") -> Não
A5: 45661 | B5: =YEAR(A5) -> 2025 | C5: =MONTH(A5) -> 1 | D5: =INDEX({"Jan","Fev","Mar","Abr","Mai","Jun","Jul","Ago","Set","Out","Nov","Dez"},C5) -> Jan | E5: =TEXT(A5,"yyyy-mm") -> 2025-01 | F5: ="T"&ROUNDUP(C5/3,0) -> T1 | G5: =INDEX({"Dom","Seg","Ter","Qua","Qui","Sex","Sáb"},WEEKDAY(A5)) -> Sáb | H5: =IF(OR(WEEKDAY(A5)=1,WEEKDAY(A5)=7),"Sim","Não") -> Sim
A6: 45662 | B6: =YEAR(A6) -> 2025 | C6: =MONTH(A6) -> 1 | D6: =INDEX({"Jan","Fev","Mar","Abr","Mai","Jun","Jul","Ago","Set","Out","Nov","Dez"},C6) -> Jan | E6: =TEXT(A6,"yyyy-mm") -> 2025-01 | F6: ="T"&ROUNDUP(C6/3,0) -> T1 | G6: =INDEX({"Dom","Seg","Ter","Qua","Qui","Sex","Sáb"},WEEKDAY(A6)) -> Dom | H6: =IF(OR(WEEKDAY(A6)=1,WEEKDAY(A6)=7),"Sim","Não") -> Sim
A7: 45663 | B7: =YEAR(A7) -> 2025 | C7: =MONTH(A7) -> 1 | D7: =INDEX({"Jan","Fev","Mar","Abr","Mai","Jun","Jul","Ago","Set","Out","Nov","Dez"},C7) -> Jan | E7: =TEXT(A7,"yyyy-mm") -> 2025-01 | F7: ="T"&ROUNDUP(C7/3,0) -> T1 | G7: =INDEX({"Dom","Seg","Ter","Qua","Qui","Sex","Sáb"},WEEKDAY(A7)) -> Seg | H7: =IF(OR(WEEKDAY(A7)=1,WEEKDAY(A7)=7),"Sim","Não") -> Não
A8: 45664 | B8: =YEAR(A8) -> 2025 | C8: =MONTH(A8) -> 1 | D8: =INDEX({"Jan","Fev","Mar","Abr","Mai","Jun","Jul","Ago","Set","Out","Nov","Dez"},C8) -> Jan | E8: =TEXT(A8,"yyyy-mm") -> 2025-01 | F8: ="T"&ROUNDUP(C8/3,0) -> T1 | G8: =INDEX({"Dom","Seg","Ter","Qua","Qui","Sex","Sáb"},WEEKDAY(A8)) -> Ter | H8: =IF(OR(WEEKDAY(A8)=1,WEEKDAY(A8)=7),"Sim","Não") -> Não
A9: 45665 | B9: =YEAR(A9) -> 2025 | C9: =MONTH(A9) -> 1 | D9: =INDEX({"Jan","Fev","Mar","Abr","Mai","Jun","Jul","Ago","Set","Out","Nov","Dez"},C9) -> Jan | E9: =TEXT(A9,"yyyy-mm") -> 2025-01 | F9: ="T"&ROUNDUP(C9/3,0) -> T1 | G9: =INDEX({"Dom","Seg","Ter","Qua","Qui","Sex","Sáb"},WEEKDAY(A9)) -> Qua | H9: =IF(OR(WEEKDAY(A9)=1,WEEKDAY(A9)=7),"Sim","Não") -> Não
A10: 45666 | B10: =YEAR(A10) -> 2025 | C10: =MONTH(A10) -> 1 | D10: =INDEX({"Jan","Fev","Mar","Abr","Mai","Jun","Jul","Ago","Set","Out","Nov","Dez"},C10) -> Jan | E10: =TEXT(A10,"yyyy-mm") -> 2025-01 | F10: ="T"&ROUNDUP(C10/3,0) -> T1 | G10: =INDEX({"Dom","Seg","Ter","Qua","Qui","Sex","Sáb"},WEEKDAY(A10)) -> Qui | H10: =IF(OR(WEEKDAY(A10)=1,WEEKDAY(A10)=7),"Sim","Não") -> Não
A11: 45667 | B11: =YEAR(A11) -> 2025 | C11: =MONTH(A11) -> 1 | D11: =INDEX({"Jan","Fev","Mar","Abr","Mai","Jun","Jul","Ago","Set","Out","Nov","Dez"},C11) -> Jan | E11: =TEXT(A11,"yyyy-mm") -> 2025-01 | F11: ="T"&ROUNDUP(C11/3,0) -> T1 | G11: =INDEX({"Dom","Seg","Ter","Qua","Qui","Sex","Sáb"},WEEKDAY(A11)) -> Sex | H11: =IF(OR(WEEKDAY(A11)=1,WEEKDAY(A11)=7),"Sim","Não") -> Não
A12: 45668 | B12: =YEAR(A12) -> 2025 | C12: =MONTH(A12) -> 1 | D12: =INDEX({"Jan","Fev","Mar","Abr","Mai","Jun","Jul","Ago","Set","Out","Nov","Dez"},C12) -> Jan | E12: =TEXT(A12,"yyyy-mm") -> 2025-01 | F12: ="T"&ROUNDUP(C12/3,0) -> T1 | G12: =INDEX({"Dom","Seg","Ter","Qua","Qui","Sex","Sáb"},WEEKDAY(A12)) -> Sáb | H12: =IF(OR(WEEKDAY(A12)=1,WEEKDAY(A12)=7),"Sim","Não") -> Sim
A13: 45669 | B13: =YEAR(A13) -> 2025 | C13: =MONTH(A13) -> 1 | D13: =INDEX({"Jan","Fev","Mar","Abr","Mai","Jun","Jul","Ago","Set","Out","Nov","Dez"},C13) -> Jan | E13: =TEXT(A13,"yyyy-mm") -> 2025-01 | F13: ="T"&ROUNDUP(C13/3,0) -> T1 | G13: =INDEX({"Dom","Seg","Ter","Qua","Qui","Sex","Sáb"},WEEKDAY(A13)) -> Dom | H13: =IF(OR(WEEKDAY(A13)=1,WEEKDAY(A13)=7),"Sim","Não") -> Sim
... A639: 46295 | B639: =YEAR(A639) -> 2026 | C639: =MONTH(A639) -> 9 | D639: =INDEX({"Jan","Fev","Mar","Abr","Mai","Jun","Jul","Ago","Set","Out","Nov","Dez"},C639) -> Set | E639: =TEXT(A639,"yyyy-mm") -> 2026-09 | F639: ="T"&ROUNDUP(C639/3,0) -> T3 | G639: =INDEX({"Dom","Seg","Ter","Qua","Qui","Sex","Sáb"},WEEKDAY(A639)) -> Qua | H639: =IF(OR(WEEKDAY(A639)=1,WEEKDAY(A639)=7),"Sim","Não") -> Não

Sheet fVendas
A1: ID_Pedido | B1: Item | C1: Data | D1: ID_Cliente | E1: ID_Produto | F1: ID_Vendedor | G1: Canal | H1: Forma_Pagamento | I1: Status | J1: Qtd | K1: Preco_Unit | L1: Desconto_% | M1: Frete | N1: Valor_Bruto | O1: Valor_Desconto | P1: Valor_Liquido | Q1: Custo_Total | R1: Lucro | S1: Categoria
A2: PED000001 | B2: 1 | C2: 45658 | D2: C0259 | E2: P017 | F2: V03 | G2: Mercado Livre | H2: Cartão de Crédito | I2: Entregue | J2: 3 | K2: 296.9 | L2: 0.05 | M2: 13.12 | N2: =J2*K2 -> 890.7 | O2: =N2*L2 -> 44.535 | P2: =N2-O2 -> 846.165 | Q2: =J2*INDEX(dProdutos!$F$2:$F$47,MATCH(E2,dProdutos!$A$2:$A$47,0)) -> 405.72 | R2: =IF(I2="Cancelado",0,P2-Q2) -> 440.445 | S2: =INDEX(dProdutos!$D$2:$D$47,MATCH(E2,dProdutos!$A$2:$A$47,0)) -> Calçados
A3: PED000002 | B3: 1 | C3: 45658 | D3: C0188 | E3: P014 | F3: V06 | G3: Loja Virtual (Nuvemshop) | H3: Cartão de Crédito | I3: Entregue | J3: 1 | K3: 166.9 | L3: 0 | M3: 0 | N3: =J3*K3 -> 166.9 | O3: =N3*L3 -> 0 | P3: =N3-O3 -> 166.9 | Q3: =J3*INDEX(dProdutos!$F$2:$F$47,MATCH(E3,dProdutos!$A$2:$A$47,0)) -> 73.23 | R3: =IF(I3="Cancelado",0,P3-Q3) -> 93.67 | S3: =INDEX(dProdutos!$D$2:$D$47,MATCH(E3,dProdutos!$A$2:$A$47,0)) -> Moda Masculina
A4: PED000003 | B4: 1 | C4: 45658 | D4: C0311 | E4: P026 | F4: V07 | G4: Loja Virtual (Nuvemshop) | H4: Cartão de Débito | I4: Entregue | J4: 1 | K4: 165.9 | L4: 0 | M4: 25.31 | N4: =J4*K4 -> 165.9 | O4: =N4*L4 -> 0 | P4: =N4-O4 -> 165.9 | Q4: =J4*INDEX(dProdutos!$F$2:$F$47,MATCH(E4,dProdutos!$A$2:$A$47,0)) -> 67.28 | R4: =IF(I4="Cancelado",0,P4-Q4) -> 98.62 | S4: =INDEX(dProdutos!$D$2:$D$47,MATCH(E4,dProdutos!$A$2:$A$47,0)) -> Acessórios
A5: PED000003 | B5: 2 | C5: 45658 | D5: C0311 | E5: P023 | F5: V07 | G5: Loja Virtual (Nuvemshop) | H5: Cartão de Débito | I5: Entregue | J5: 1 | K5: 260.9 | L5: 0 | M5: 0 | N5: =J5*K5 -> 260.9 | O5: =N5*L5 -> 0 | P5: =N5-O5 -> 260.9 | Q5: =J5*INDEX(dProdutos!$F$2:$F$47,MATCH(E5,dProdutos!$A$2:$A$47,0)) -> 99.86 | R5: =IF(I5="Cancelado",0,P5-Q5) -> 161.04 | S5: =INDEX(dProdutos!$D$2:$D$47,MATCH(E5,dProdutos!$A$2:$A$47,0)) -> Acessórios
A6: PED000004 | B6: 1 | C6: 45658 | D6: C0009 | E6: P003 | F6: V03 | G6: Shopee | H6: Cartão de Débito | I6: Entregue | J6: 3 | K6: 64.9 | L6: 0.1 | M6: 28.03 | N6: =J6*K6 -> 194.7 | O6: =N6*L6 -> 19.47 | P6: =N6-O6 -> 175.23 | Q6: =J6*INDEX(dProdutos!$F$2:$F$47,MATCH(E6,dProdutos!$A$2:$A$47,0)) -> 78.36 | R6: =IF(I6="Cancelado",0,P6-Q6) -> 96.87 | S6: =INDEX(dProdutos!$D$2:$D$47,MATCH(E6,dProdutos!$A$2:$A$47,0)) -> Moda Feminina
A7: PED000004 | B7: 2 | C7: 45658 | D7: C0009 | E7: P021 | F7: V03 | G7: Shopee | H7: Cartão de Débito | I7: Entregue | J7: 1 | K7: 231.9 | L7: 0.05 | M7: 0 | N7: =J7*K7 -> 231.9 | O7: =N7*L7 -> 11.595 | P7: =N7-O7 -> 220.305 | Q7: =J7*INDEX(dProdutos!$F$2:$F$47,MATCH(E7,dProdutos!$A$2:$A$47,0)) -> 132.21 | R7: =IF(I7="Cancelado",0,P7-Q7) -> 88.095 | S7: =INDEX(dProdutos!$D$2:$D$47,MATCH(E7,dProdutos!$A$2:$A$47,0)) -> Calçados
A8: PED000005 | B8: 1 | C8: 45658 | D8: C0370 | E8: P010 | F8: V01 | G8: Mercado Livre | H8: Cartão de Crédito | I8: Entregue | J8: 1 | K8: 175.9 | L8: 0 | M8: 19.4 | N8: =J8*K8 -> 175.9 | O8: =N8*L8 -> 0 | P8: =N8-O8 -> 175.9 | Q8: =J8*INDEX(dProdutos!$F$2:$F$47,MATCH(E8,dProdutos!$A$2:$A$47,0)) -> 96.59 | R8: =IF(I8="Cancelado",0,P8-Q8) -> 79.31 | S8: =INDEX(dProdutos!$D$2:$D$47,MATCH(E8,dProdutos!$A$2:$A$47,0)) -> Moda Masculina
A9: PED000005 | B9: 2 | C9: 45658 | D9: C0370 | E9: P025 | F9: V01 | G9: Mercado Livre | H9: Cartão de Crédito | I9: Entregue | J9: 1 | K9: 71.9 | L9: 0 | M9: 0 | N9: =J9*K9 -> 71.9 | O9: =N9*L9 -> 0 | P9: =N9-O9 -> 71.9 | Q9: =J9*INDEX(dProdutos!$F$2:$F$47,MATCH(E9,dProdutos!$A$2:$A$47,0)) -> 27.38 | R9: =IF(I9="Cancelado",0,P9-Q9) -> 44.52 | S9: =INDEX(dProdutos!$D$2:$D$47,MATCH(E9,dProdutos!$A$2:$A$47,0)) -> Acessórios
A10: PED000006 | B10: 1 | C10: 45659 | D10: C0212 | E10: P007 | F10: V06 | G10: Loja Virtual (Yampi) | H10: Cartão de Crédito | I10: Cancelado | J10: 1 | K10: 77.9 | L10: 0 | M10: 28.3 | N10: =J10*K10 -> 77.9 | O10: =N10*L10 -> 0 | P10: =N10-O10 -> 77.9 | Q10: =J10*INDEX(dProdutos!$F$2:$F$47,MATCH(E10,dProdutos!$A$2:$A$47,0)) -> 36.71 | R10: =IF(I10="Cancelado",0,P10-Q10) -> 0 | S10: =INDEX(dProdutos!$D$2:$D$47,MATCH(E10,dProdutos!$A$2:$A$47,0)) -> Moda Feminina
A11: PED000007 | B11: 1 | C11: 45659 | D11: C0340 | E11: P037 | F11: V04 | G11: Loja Virtual (Yampi) | H11: Cartão de Débito | I11: Entregue | J11: 2 | K11: 120.9 | L11: 0 | M11: 23.56 | N11: =J11*K11 -> 241.8 | O11: =N11*L11 -> 0 | P11: =N11-O11 -> 241.8 | Q11: =J11*INDEX(dProdutos!$F$2:$F$47,MATCH(E11,dProdutos!$A$2:$A$47,0)) -> 144.42 | R11: =IF(I11="Cancelado",0,P11-Q11) -> 97.38 | S11: =INDEX(dProdutos!$D$2:$D$47,MATCH(E11,dProdutos!$A$2:$A$47,0)) -> Eletrônicos
A12: PED000007 | B12: 2 | C12: 45659 | D12: C0340 | E12: P030 | F12: V04 | G12: Loja Virtual (Yampi) | H12: Cartão de Débito | I12: Entregue | J12: 1 | K12: 231.9 | L12: 0.2 | M12: 0 | N12: =J12*K12 -> 231.9 | O12: =N12*L12 -> 46.38 | P12: =N12-O12 -> 185.52 | Q12: =J12*INDEX(dProdutos!$F$2:$F$47,MATCH(E12,dProdutos!$A$2:$A$47,0)) -> 140.83 | R12: =IF(I12="Cancelado",0,P12-Q12) -> 44.69 | S12: =INDEX(dProdutos!$D$2:$D$47,MATCH(E12,dProdutos!$A$2:$A$47,0)) -> Casa
A13: PED000008 | B13: 1 | C13: 45659 | D13: C0143 | E13: P031 | F13: V04 | G13: Loja Virtual (Nuvemshop) | H13: Cartão de Débito | I13: Entregue | J13: 1 | K13: 253.9 | L13: 0 | M13: 0 | N13: =J13*K13 -> 253.9 | O13: =N13*L13 -> 0 | P13: =N13-O13 -> 253.9 | Q13: =J13*INDEX(dProdutos!$F$2:$F$47,MATCH(E13,dProdutos!$A$2:$A$47,0)) -> 128.94 | R13: =IF(I13="Cancelado",0,P13-Q13) -> 124.96 | S13: =INDEX(dProdutos!$D$2:$D$47,MATCH(E13,dProdutos!$A$2:$A$47,0)) -> Casa
... A9799: PED005991 | B9799: 4 | C9799: 46295 | D9799: C0383 | E9799: P009 | F9799: V08 | G9799: Loja Virtual (Yampi) | H9799: Pix | I9799: Em trânsito | J9799: 1 | K9799: 65.9 | L9799: 0.05 | M9799: 0 | N9799: =J9799*K9799 -> 65.9 | O9799: =N9799*L9799 -> 3.295 | P9799: =N9799-O9799 -> 62.605 | Q9799: =J9799*INDEX(dProdutos!$F$2:$F$47,MATCH(E9799,dProdutos!$A$2:$A$47,0)) -> 29.68 | R9799: =IF(I9799="Cancelado",0,P9799-Q9799) -> 32.925 | S9799: =INDEX(dProdutos!$D$2:$D$47,MATCH(E9799,dProdutos!$A$2:$A$47,0)) -> Moda Masculina

Sheet fCompras
A1: NF_Entrada | B1: Data_Entrada | C1: ID_Produto | D1: Fornecedor | E1: Qtd | F1: Custo_Unit | G1: Custo_Total
A2: NF00001 | B2: 45658 | C2: P044 | D2: Fábrica Própria | E2: 30 | F2: 88.34 | G2: =E2*F2 -> 2650.2
A3: NF00002 | B3: 45659 | C3: P003 | D3: Atacado Brás SP | E3: 30 | F3: 27.21 | G3: =E3*F3 -> 816.3
A4: NF00003 | B4: 45659 | C4: P017 | D4: Import Sul | E4: 50 | F4: 135.22 | G4: =E4*F4 -> 6761
A5: NF00004 | B5: 45659 | C5: P027 | D5: Atacado Brás SP | E5: 100 | F5: 82.14 | G5: =E5*F5 -> 8214
A6: NF00005 | B6: 45660 | C6: P015 | D6: Dropi Distribuidora | E6: 55 | F6: 43.94 | G6: =E6*F6 -> 2416.7
A7: NF00006 | B7: 45660 | C7: P024 | D7: Fornecedor Goiânia | E7: 23 | F7: 130.1 | G7: =E7*F7 -> 2992.3
A8: NF00007 | B8: 45661 | C8: P020 | D8: Dropi Distribuidora | E8: 150 | F8: 79.36 | G8: =E8*F8 -> 11904
A9: NF00008 | B9: 45661 | C9: P030 | D9: Dropi Distribuidora | E9: 150 | F9: 139.44 | G9: =E9*F9 -> 20916
A10: NF00009 | B10: 45662 | C10: P012 | D10: Fornecedor Goiânia | E10: 145 | F10: 86.33 | G10: =E10*F10 -> 12517.85
A11: NF00010 | B11: 45662 | C11: P026 | D11: Fornecedor Goiânia | E11: 100 | F11: 65.86 | G11: =E11*F11 -> 6586
A12: NF00011 | B12: 45662 | C12: P033 | D12: Atacado Brás SP | E12: 80 | F12: 148.8 | G12: =E12*F12 -> 11904
A13: NF00012 | B13: 45663 | C13: P005 | D13: Dropi Distribuidora | E13: 30 | F13: 95.35 | G13: =E13*F13 -> 2860.5
... A155: NF00154 | B155: 45938 | C155: P005 | D155: Dropi Distribuidora | E155: 46 | F155: 96.48 | G155: =E155*F155 -> 4438.08

Sheet fEstoque
A1: ID_Produto | B1: Produto | C1: Estoque_Inicial | D1: Entradas | E1: Saidas | F1: Estoque_Atual | G1: Estoque_Minimo | H1: Status | I1: Valor_em_Estoque
A2: P001 | B2: =INDEX(dProdutos!$C$2:$C$47,MATCH(A2,dProdutos!$A$2:$A$47,0)) -> Vestido Midi | C2: 69 | D2: =SUMIFS(fCompras!$E$2:$E$155,fCompras!$C$2:$C$155,A2) -> 116 | E2: =SUMIFS(fVendas!$J$2:$J$9799,fVendas!$E$2:$E$9799,A2,fVendas!$I$2:$I$9799,"<>Cancelado") -> 184 | F2: =C2+D2-E2 -> 1 | G2: =INDEX(dProdutos!$I$2:$I$47,MATCH(A2,dProdutos!$A$2:$A$47,0)) -> 15 | H2: =IF(F2<=0,"SEM ESTOQUE",IF(F2<G2,"REPOR","OK")) -> REPOR | I2: =F2*INDEX(dProdutos!$F$2:$F$47,MATCH(A2,dProdutos!$A$2:$A$47,0)) -> 69.44
A3: P002 | B3: =INDEX(dProdutos!$C$2:$C$47,MATCH(A3,dProdutos!$A$2:$A$47,0)) -> Blusa Cropped | C3: 52 | D3: =SUMIFS(fCompras!$E$2:$E$155,fCompras!$C$2:$C$155,A3) -> 67 | E3: =SUMIFS(fVendas!$J$2:$J$9799,fVendas!$E$2:$E$9799,A3,fVendas!$I$2:$I$9799,"<>Cancelado") -> 118 | F3: =C3+D3-E3 -> 1 | G3: =INDEX(dProdutos!$I$2:$I$47,MATCH(A3,dProdutos!$A$2:$A$47,0)) -> 25 | H3: =IF(F3<=0,"SEM ESTOQUE",IF(F3<G3,"REPOR","OK")) -> REPOR | I3: =F3*INDEX(dProdutos!$F$2:$F$47,MATCH(A3,dProdutos!$A$2:$A$47,0)) -> 107.88
A4: P003 | B4: =INDEX(dProdutos!$C$2:$C$47,MATCH(A4,dProdutos!$A$2:$A$47,0)) -> Calça Wide Leg | C4: 106 | D4: =SUMIFS(fCompras!$E$2:$E$155,fCompras!$C$2:$C$155,A4) -> 203 | E4: =SUMIFS(fVendas!$J$2:$J$9799,fVendas!$E$2:$E$9799,A4,fVendas!$I$2:$I$9799,"<>Cancelado") -> 282 | F4: =C4+D4-E4 -> 27 | G4: =INDEX(dProdutos!$I$2:$I$47,MATCH(A4,dProdutos!$A$2:$A$47,0)) -> 10 | H4: =IF(F4<=0,"SEM ESTOQUE",IF(F4<G4,"REPOR","OK")) -> OK | I4: =F4*INDEX(dProdutos!$F$2:$F$47,MATCH(A4,dProdutos!$A$2:$A$47,0)) -> 705.24
A5: P004 | B5: =INDEX(dProdutos!$C$2:$C$47,MATCH(A5,dProdutos!$A$2:$A$47,0)) -> Saia Plissada | C5: 56 | D5: =SUMIFS(fCompras!$E$2:$E$155,fCompras!$C$2:$C$155,A5) -> 254 | E5: =SUMIFS(fVendas!$J$2:$J$9799,fVendas!$E$2:$E$9799,A5,fVendas!$I$2:$I$9799,"<>Cancelado") -> 256 | F5: =C5+D5-E5 -> 54 | G5: =INDEX(dProdutos!$I$2:$I$47,MATCH(A5,dProdutos!$A$2:$A$47,0)) -> 25 | H5: =IF(F5<=0,"SEM ESTOQUE",IF(F5<G5,"REPOR","OK")) -> OK | I5: =F5*INDEX(dProdutos!$F$2:$F$47,MATCH(A5,dProdutos!$A$2:$A$47,0)) -> 4943.7
A6: P005 | B6: =INDEX(dProdutos!$C$2:$C$47,MATCH(A6,dProdutos!$A$2:$A$47,0)) -> Macacão Longo | C6: 88 | D6: =SUMIFS(fCompras!$E$2:$E$155,fCompras!$C$2:$C$155,A6) -> 336 | E6: =SUMIFS(fVendas!$J$2:$J$9799,fVendas!$E$2:$E$9799,A6,fVendas!$I$2:$I$9799,"<>Cancelado") -> 415 | F6: =C6+D6-E6 -> 9 | G6: =INDEX(dProdutos!$I$2:$I$47,MATCH(A6,dProdutos!$A$2:$A$47,0)) -> 15 | H6: =IF(F6<=0,"SEM ESTOQUE",IF(F6<G6,"REPOR","OK")) -> REPOR | I6: =F6*INDEX(dProdutos!$F$2:$F$47,MATCH(A6,dProdutos!$A$2:$A$47,0)) -> 883.26
A7: P006 | B7: =INDEX(dProdutos!$C$2:$C$47,MATCH(A7,dProdutos!$A$2:$A$47,0)) -> Blazer Alfaiataria | C7: 47 | D7: =SUMIFS(fCompras!$E$2:$E$155,fCompras!$C$2:$C$155,A7) -> 140 | E7: =SUMIFS(fVendas!$J$2:$J$9799,fVendas!$E$2:$E$9799,A7,fVendas!$I$2:$I$9799,"<>Cancelado") -> 136 | F7: =C7+D7-E7 -> 51 | G7: =INDEX(dProdutos!$I$2:$I$47,MATCH(A7,dProdutos!$A$2:$A$47,0)) -> 20 | H7: =IF(F7<=0,"SEM ESTOQUE",IF(F7<G7,"REPOR","OK")) -> OK | I7: =F7*INDEX(dProdutos!$F$2:$F$47,MATCH(A7,dProdutos!$A$2:$A$47,0)) -> 4518.09
A8: P007 | B8: =INDEX(dProdutos!$C$2:$C$47,MATCH(A8,dProdutos!$A$2:$A$47,0)) -> Cardigan Tricô | C8: 82 | D8: =SUMIFS(fCompras!$E$2:$E$155,fCompras!$C$2:$C$155,A8) -> 391 | E8: =SUMIFS(fVendas!$J$2:$J$9799,fVendas!$E$2:$E$9799,A8,fVendas!$I$2:$I$9799,"<>Cancelado") -> 463 | F8: =C8+D8-E8 -> 10 | G8: =INDEX(dProdutos!$I$2:$I$47,MATCH(A8,dProdutos!$A$2:$A$47,0)) -> 30 | H8: =IF(F8<=0,"SEM ESTOQUE",IF(F8<G8,"REPOR","OK")) -> REPOR | I8: =F8*INDEX(dProdutos!$F$2:$F$47,MATCH(A8,dProdutos!$A$2:$A$47,0)) -> 367.1
A9: P008 | B9: =INDEX(dProdutos!$C$2:$C$47,MATCH(A9,dProdutos!$A$2:$A$47,0)) -> Short Jeans | C9: 61 | D9: =SUMIFS(fCompras!$E$2:$E$155,fCompras!$C$2:$C$155,A9) -> 291 | E9: =SUMIFS(fVendas!$J$2:$J$9799,fVendas!$E$2:$E$9799,A9,fVendas!$I$2:$I$9799,"<>Cancelado") -> 296 | F9: =C9+D9-E9 -> 56 | G9: =INDEX(dProdutos!$I$2:$I$47,MATCH(A9,dProdutos!$A$2:$A$47,0)) -> 25 | H9: =IF(F9<=0,"SEM ESTOQUE",IF(F9<G9,"REPOR","OK")) -> OK | I9: =F9*INDEX(dProdutos!$F$2:$F$47,MATCH(A9,dProdutos!$A$2:$A$47,0)) -> 2381.12
A10: P009 | B10: =INDEX(dProdutos!$C$2:$C$47,MATCH(A10,dProdutos!$A$2:$A$47,0)) -> Camiseta Básica | C10: 82 | D10: =SUMIFS(fCompras!$E$2:$E$155,fCompras!$C$2:$C$155,A10) -> 361 | E10: =SUMIFS(fVendas!$J$2:$J$9799,fVendas!$E$2:$E$9799,A10,fVendas!$I$2:$I$9799,"<>Cancelado") -> 424 | F10: =C10+D10-E10 -> 19 | G10: =INDEX(dProdutos!$I$2:$I$47,MATCH(A10,dProdutos!$A$2:$A$47,0)) -> 20 | H10: =IF(F10<=0,"SEM ESTOQUE",IF(F10<G10,"REPOR","OK")) -> REPOR | I10: =F10*INDEX(dProdutos!$F$2:$F$47,MATCH(A10,dProdutos!$A$2:$A$47,0)) -> 563.92
A11: P010 | B11: =INDEX(dProdutos!$C$2:$C$47,MATCH(A11,dProdutos!$A$2:$A$47,0)) -> Camisa Social | C11: 41 | D11: =SUMIFS(fCompras!$E$2:$E$155,fCompras!$C$2:$C$155,A11) -> 334 | E11: =SUMIFS(fVendas!$J$2:$J$9799,fVendas!$E$2:$E$9799,A11,fVendas!$I$2:$I$9799,"<>Cancelado") -> 373 | F11: =C11+D11-E11 -> 2 | G11: =INDEX(dProdutos!$I$2:$I$47,MATCH(A11,dProdutos!$A$2:$A$47,0)) -> 20 | H11: =IF(F11<=0,"SEM ESTOQUE",IF(F11<G11,"REPOR","OK")) -> REPOR | I11: =F11*INDEX(dProdutos!$F$2:$F$47,MATCH(A11,dProdutos!$A$2:$A$47,0)) -> 193.18
A12: P011 | B12: =INDEX(dProdutos!$C$2:$C$47,MATCH(A12,dProdutos!$A$2:$A$47,0)) -> Bermuda Sarja | C12: 99 | D12: =SUMIFS(fCompras!$E$2:$E$155,fCompras!$C$2:$C$155,A12) -> 160 | E12: =SUMIFS(fVendas!$J$2:$J$9799,fVendas!$E$2:$E$9799,A12,fVendas!$I$2:$I$9799,"<>Cancelado") -> 249 | F12: =C12+D12-E12 -> 10 | G12: =INDEX(dProdutos!$I$2:$I$47,MATCH(A12,dProdutos!$A$2:$A$47,0)) -> 25 | H12: =IF(F12<=0,"SEM ESTOQUE",IF(F12<G12,"REPOR","OK")) -> REPOR | I12: =F12*INDEX(dProdutos!$F$2:$F$47,MATCH(A12,dProdutos!$A$2:$A$47,0)) -> 1556.2
A13: P012 | B13: =INDEX(dProdutos!$C$2:$C$47,MATCH(A13,dProdutos!$A$2:$A$47,0)) -> Calça Chino | C13: 97 | D13: =SUMIFS(fCompras!$E$2:$E$155,fCompras!$C$2:$C$155,A13) -> 145 | E13: =SUMIFS(fVendas!$J$2:$J$9799,fVendas!$E$2:$E$9799,A13,fVendas!$I$2:$I$9799,"<>Cancelado") -> 223 | F13: =C13+D13-E13 -> 19 | G13: =INDEX(dProdutos!$I$2:$I$47,MATCH(A13,dProdutos!$A$2:$A$47,0)) -> 20 | H13: =IF(F13<=0,"SEM ESTOQUE",IF(F13<G13,"REPOR","OK")) -> REPOR | I13: =F13*INDEX(dProdutos!$F$2:$F$47,MATCH(A13,dProdutos!$A$2:$A$47,0)) -> 1678.08
... A47: P046 | B47: =INDEX(dProdutos!$C$2:$C$47,MATCH(A47,dProdutos!$A$2:$A$47,0)) -> Hidratante Corporal | C47: 73 | D47: =SUMIFS(fCompras!$E$2:$E$155,fCompras!$C$2:$C$155,A47) -> 64 | E47: =SUMIFS(fVendas!$J$2:$J$9799,fVendas!$E$2:$E$9799,A47,fVendas!$I$2:$I$9799,"<>Cancelado") -> 122 | F47: =C47+D47-E47 -> 15 | G47: =INDEX(dProdutos!$I$2:$I$47,MATCH(A47,dProdutos!$A$2:$A$47,0)) -> 10 | H47: =IF(F47<=0,"SEM ESTOQUE",IF(F47<G47,"REPOR","OK")) -> OK | I47: =F47*INDEX(dProdutos!$F$2:$F$47,MATCH(A47,dProdutos!$A$2:$A$47,0)) -> 1356.3

Sheet Base_Suja
A1: cod cliente | B1: NOME CLIENTE | C1: e-mail | D1: Telefone | E1: cidade | F1: Estado | G1: dt cadastro | H1: Total Gasto
A2: C0121 | B2: João Rocha | C2: JOAO.ROCHA121@EXEMPLO.COM | D2: 47 967564075 | E2: Rio de Janeiro | F2: rj | G2: 16.11.2025 | H2: 2388.66
A3: C0088 | B3: Marcos Ferreira | C3: marcos.ferreira88@exemplo.com | D3: +5554983708516 | E3: são paulo | F3: São Paulo | G3: 2024-12-20
A4: C0279 | B4: Juliana Dias | C4: JULIANA.DIAS279@EXEMPLO.COM | D4: 72915093895 | E4: Florianopolis | F4: sc | G4: 2024-02-07
A5: C0436 | B5: EDUARDO MARTINS | C5: eduardo.martins436@exemplo.com | D5: +5550947694644 | E5: são paulo | F5: sp | G5: 11-12-24 | H5: R$ 2.107,69
A6: C0347 | B6: gustavo barbosa | C6: gustavo.barbosa347@exemplo.com | D6: 91979134530 | E6: curitiba | F6: PR | G6: 11.05.2024
A7: C0344 | B7: Lucas Pereira | C7: lucas.pereira344@exemplo.com | D7: 58 932678625 | E7: curitiba | F7: PR | G7: 09-10-24
A8: C0348 | B8: Natália Moreira | C8: NATALIA.MOREIRA348@EXEMPLO.COM | D8: (75) 92108-4181 | E8: São Paulo | F8: SP | G8: 10.08.2024 | H8: 1855.64
A9: C0389 | B9: FERNANDA COSTA | C9: fernanda.costa389@exemplo.com | D9: 19965267342 | E9: florianópolis | F9: SC | G9: 06-10-24 | H9: 620,12
A10: C0164 | B10: thiago silva | C10: thiago.silva164@exemplo.com | D10: +5592978996022 | E10: Florianopolis | F10: SC | G10: 05-06-25 | H10: 2706,02
A11: C0300 | B11: Marcos Ribeiro | C11: marcos.ribeiro300@exemplo.com | D11: (53) 91663-7800 | E11: SÃO PAULO | F11: São Paulo | G11: 2026-04-10 | H11: 574,34
A12: C0276 | B12: Beatriz Moreira | C12: beatriz.moreira276@exemplo.com | D12: 55 959829789 | E12: Brasília | F12: df | G12: 26-03-26
A13: C0184 | B13: Igor Santos | C13: IGOR.SANTOS184@EXEMPLO.COM | D13: (56) 97674-1115 | E13: rio de janeiro | F13: Rio | G13: 26-03-25
A14: C0272 | B14: patrícia rodrigues | C14: PATRICIA.RODRIGUES272@EXEMPLO.COM | D14: (54) 96211-7028 | E14: Florianópolis | F14: SC | G14: 14.07.2024 | H14: R$ 2.962,41
A15: C0351 | B15: FERNANDA FERREIRA | C15: fernanda.ferreira351@exemplo.com | D15: 58974095600 | E15: Rio de Janeiro | F15: Rio | G15: 06-05-25 | H15: 2629.95
A16: C0376 | B16: mariana rodrigues | C16: MARIANA.RODRIGUES376@EXEMPLO.COM | D16: +5581935183668 | E16: SÃO PAULO | F16: SP | G16: 30-01-26 | H16: 1974,11
A17: C0178 | B17: Igor Costa | C17: igor.costa178@exemplo.com | D17: 91 991853041 | E17: Brasília | F17: df | G17: 30.04.2025 | H17: R$ 1.257,90
A18: C0380 | B18: Pedro Lima | C18: pedro.lima380@exemplo.com | D18: 82933354305 | E18: São Paulo | F18: sp | G18: 20/09/2025
A19: C0018 | B19: Bruno Moreira | C19: bruno.moreira18@exemplo.com | D19: 81 928412764 | E19: Belém | F19: PA | G19: 03-03-26 | H19: R$ 2.425,23
A20: C0260 | B20: ANDRÉ ALMEIDA | C20: andre.almeida260@exemplo.com | D20: (96) 93744-9486 | E20: Curitiba | F20: pr | G20: 2025-02-10 | H20: R$ 2.337,62
A21: C0029 | B21: Juliana Rocha | C21: juliana.rocha29@exemplo.com | D21: (14) 94299-1205 | E21: SÃO PAULO | F21: SP | G21: 2024-12-10 | H21: R$ 2.071,53
A22: C0033 | B22: IGOR MOREIRA | C22: IGOR.MOREIRA33@EXEMPLO.COM | D22: +5563982675830 | E22: Recife | F22: pe | G22: 27.07.2024 | H22: R$ 2.464,60
A23: C0130 | B23: RAFAEL SOUZA | C23: rafael.souza130@exemplo.com | D23: (34) 98696-9636 | E23: Goiânia | F23: GO | G23: 07/07/2025 | H23: 1401.42
A24: C0345 | B24: Pedro Alves | C24: pedro.alves345@exemplo.com | D24: +5577954289421 | E24: RIO DE JANEIRO | F24: Rio | G24: 04/07/2025
A25: C0321 | B25: Daniel Oliveira | C25: daniel.oliveira321@exemplo.com | D25: (40) 95592-6674 | E25: curitiba | F25: PR | G25: 22-05-24 | H25: R$ 866,61
A26: C0211 | B26: ANDRÉ SILVA | C26: andre.silva211@exemplo.com | D26: 14 979294176 | E26: BELÉM | F26: PA | G26: 02.10.2025 | H26: 1754.15
A27: C0072 | B27: Pedro Almeida | C27: pedro.almeida72@exemplo.com | D27: 30950032459 | E27: campinas | F27: SP | G27: 2024-08-07 | H27: 966.25
A28: C0437 | B28: THIAGO ROCHA | C28: thiago.rocha437@exemplo.com | D28: (69) 96670-2184 | E28: SÃO PAULO | F28: sp | G28: 01-08-24 | H28: R$ 2.616,63
A29: C0105 | B29: rafael souza | C29: rafael.souza105@exemplo.com | D29: +5523978432287 | E29: Belo Horizonte | F29: Minas | G29: 02.12.2024 | H29: 2667,6
A30: C0385 | B30: Rafael Lopes | C30: RAFAEL.LOPES385@EXEMPLO.COM | D30: (71) 92369-4168 | E30: Rio de Janeiro | F30: rj | G30: 21-02-26 | H30: 869.23
A31: C0409 | B31: ANDRÉ GOMES | C31: andre.gomes409@exemplo.com | D31: 29945342785 | E31: goiânia | F31: GO | G31: 25-11-25
A32: C0131 | B32: André Lopes | C32: andre.lopes131@exemplo.com | D32: 62957011688 | E32: Curitiba | F32: pr | G32: 10.11.2024 | H32: 784.86
A34: C0378 | B34: NATÁLIA SANTOS | C34: natalia.santos378@exemplo.com | D34: +5538911951061 | E34: Rio de Janeiro | F34: RJ | G34: 10-10-24 | H34: R$ 2.926,01
A35: C0077 | B35: Juliana Alves | C35: juliana.alves77@exemplo.com | D35: 54 977728722 | E35: SÃO PAULO | F35: São Paulo | G35: 18.01.2025
A36: C0432 | B36: Henrique Gomes | C36: henrique.gomes432@exemplo.com | D36: 22 981582323 | E36: belo horizonte | F36: mg | G36: 02.11.2025 | H36: 2199.8
A37: C0262 | B37: PATRÍCIA CARVALHO | C37: patricia.carvalho262@exemplo.com | D37: +5593956615441 | E37: belo horizonte | F37: MG | G37: 18.07.2024
A38: C0129 | B38: andré rodrigues | C38: andre.rodrigues129@exemplo.com | D38: (56) 99991-9746 | E38: florianópolis | F38: SC | G38: 06.01.2026 | H38: 2032,48
A39: C0224 | B39: HENRIQUE ROCHA | C39: HENRIQUE.ROCHA224@EXEMPLO.COM | D39: +5582997756551 | E39: Rio de Janeiro | F39: RJ | G39: 2026-02-14
A40: C0220 | B40: Felipe Barbosa | C40: felipe.barbosa220@exemplo.com | D40: (29) 97103-9076 | E40: curitiba | F40: PR | G40: 02/09/2024 | H40: 2102,01
A41: C0044 | B41: MARIANA DIAS | C41: mariana.dias44@exemplo.com | D41: +5512940872547 | E41: manaus | F41: am | G41: 25-08-24 | H41: 2389.54
...
